Traceback (most recent call last):
  File "/opt/hostedtoolcache/Python/3.8.15/x64/lib/python3.8/site-packages/jupyter_cache/executors/utils.py", line 58, in single_nb_execution
    executenb(
  File "/opt/hostedtoolcache/Python/3.8.15/x64/lib/python3.8/site-packages/nbclient/client.py", line 1204, in execute
    return NotebookClient(nb=nb, resources=resources, km=km, **kwargs).execute()
  File "/opt/hostedtoolcache/Python/3.8.15/x64/lib/python3.8/site-packages/nbclient/util.py", line 84, in wrapped
    return just_run(coro(*args, **kwargs))
  File "/opt/hostedtoolcache/Python/3.8.15/x64/lib/python3.8/site-packages/nbclient/util.py", line 62, in just_run
    return loop.run_until_complete(coro)
  File "/opt/hostedtoolcache/Python/3.8.15/x64/lib/python3.8/asyncio/base_events.py", line 616, in run_until_complete
    return future.result()
  File "/opt/hostedtoolcache/Python/3.8.15/x64/lib/python3.8/site-packages/nbclient/client.py", line 663, in async_execute
    await self.async_execute_cell(
  File "/opt/hostedtoolcache/Python/3.8.15/x64/lib/python3.8/site-packages/nbclient/client.py", line 965, in async_execute_cell
    await self._check_raise_for_error(cell, cell_index, exec_reply)
  File "/opt/hostedtoolcache/Python/3.8.15/x64/lib/python3.8/site-packages/nbclient/client.py", line 862, in _check_raise_for_error
    raise CellExecutionError.from_cell_and_msg(cell, exec_reply_content)
nbclient.exceptions.CellExecutionError: An error occurred while executing the following cell:
------------------
log = calc.run(sys=sys, input=inp, name="quick", run_dir="scratch")
------------------

[0;31m---------------------------------------------------------------------------[0m
[0;31mAttributeError[0m                            Traceback (most recent call last)
Cell [0;32mIn[33], line 1[0m
[0;32m----> 1[0m log [38;5;241m=[39m [43mcalc[49m[38;5;241;43m.[39;49m[43mrun[49m[43m([49m[43msys[49m[38;5;241;43m=[39;49m[43msys[49m[43m,[49m[43m [49m[38;5;28;43minput[39;49m[38;5;241;43m=[39;49m[43minp[49m[43m,[49m[43m [49m[43mname[49m[38;5;241;43m=[39;49m[38;5;124;43m"[39;49m[38;5;124;43mquick[39;49m[38;5;124;43m"[39;49m[43m,[49m[43m [49m[43mrun_dir[49m[38;5;241;43m=[39;49m[38;5;124;43m"[39;49m[38;5;124;43mscratch[39;49m[38;5;124;43m"[39;49m[43m)[49m

File [0;32m/opt/hostedtoolcache/Python/3.8.15/x64/lib/python3.8/site-packages/BigDFT/Calculators.py:263[0m, in [0;36mRunner.run[0;34m(self, **kwargs)[0m
[1;32m    261[0m dict_merge(dest[38;5;241m=[39mrun_args, src[38;5;241m=[39mrun_results)
[1;32m    262[0m [38;5;66;03m# safe_print('run_updated, again',run_args)[39;00m
[0;32m--> 263[0m [38;5;28;01mreturn[39;00m [38;5;28;43mself[39;49m[38;5;241;43m.[39;49m[43mpost_processing[49m[43m([49m[38;5;241;43m*[39;49m[38;5;241;43m*[39;49m[43mrun_args[49m[43m)[49m

File [0;32m/opt/hostedtoolcache/Python/3.8.15/x64/lib/python3.8/site-packages/BigDFT/Calculators.py:544[0m, in [0;36mSystemCalculator.post_processing[0;34m(self, timedbg, logname, command)[0m
[1;32m    542[0m         [38;5;28;01mreturn[39;00m [38;5;28;01mNone[39;00m
[1;32m    543[0m     [38;5;28;01melse[39;00m:
[0;32m--> 544[0m         [38;5;28;01mreturn[39;00m [43mLf[49m[38;5;241;43m.[39;49m[43mLogfile[49m[43m([49m[43mlogname[49m[43m)[49m
[1;32m    545[0m [38;5;28;01melse[39;00m:
[1;32m    546[0m     [38;5;66;03m# there can be an error file within this folder[39;00m
[1;32m    547[0m     [38;5;66;03m# if so, print the contents of that[39;00m
[1;32m    548[0m     [38;5;66;03m# it will be more useful than the fallback error[39;00m
[1;32m    549[0m     [38;5;66;03m#[39;00m
[1;32m    550[0m     [38;5;66;03m# logpath, sans any spurious '.' from ./ path entities[39;00m
[1;32m    551[0m     logpath [38;5;241m=[39m os[38;5;241m.[39mpath[38;5;241m.[39msplit(logname)[[38;5;241m0[39m][38;5;241m.[39mrstrip([38;5;124m'[39m[38;5;124m.[39m[38;5;124m'[39m)

File [0;32m/opt/hostedtoolcache/Python/3.8.15/x64/lib/python3.8/site-packages/BigDFT/Logfiles.py:417[0m, in [0;36mLogfile.__init__[0;34m(self, *args, **kwargs)[0m
[1;32m    414[0m     [38;5;28;01mraise[39;00m [38;5;167;01mValueError[39;00m([38;5;124m"[39m[38;5;124mNo log information provided.[39m[38;5;124m"[39m)
[1;32m    415[0m [38;5;66;03m# So we have a list of a dictionary or a list of dictionaries[39;00m
[1;32m    416[0m [38;5;66;03m# Initialize the logfile with the first document[39;00m
[0;32m--> 417[0m [38;5;28;43mself[39;49m[38;5;241;43m.[39;49m[43m_initialize_class[49m[43m([49m[43mdicts[49m[43m[[49m[38;5;241;43m0[39;49m[43m][49m[43m)[49m
[1;32m    418[0m [38;5;66;03m#[39;00m
[1;32m    419[0m [38;5;28;01mif[39;00m [38;5;28mlen[39m(dicts) [38;5;241m>[39m [38;5;241m1[39m:
[1;32m    420[0m     [38;5;66;03m# first initialize the instances with the previous logfile such as[39;00m
[1;32m    421[0m     [38;5;66;03m# to provide the correct information (we should however decide what[39;00m
[1;32m    422[0m     [38;5;66;03m# to do if some run did not converged)[39;00m

File [0;32m/opt/hostedtoolcache/Python/3.8.15/x64/lib/python3.8/site-packages/BigDFT/Logfiles.py:520[0m, in [0;36mLogfile._initialize_class[0;34m(self, d)[0m
[1;32m    517[0m     [38;5;28;01mfrom[39;00m [38;5;21;01mBigDFT[39;00m [38;5;28;01mimport[39;00m BZ
[1;32m    518[0m     [38;5;66;03m#: Eigenvalues of the run, represented as a[39;00m
[1;32m    519[0m     [38;5;66;03m#  :class:`BigDFT.BZ.BandArray` class instance[39;00m
[0;32m--> 520[0m     [38;5;28mself[39m[38;5;241m.[39mevals [38;5;241m=[39m [[43mBZ[49m[38;5;241;43m.[39;49m[43mBandArray[49m[43m([49m[38;5;28;43mself[39;49m[38;5;241;43m.[39;49m[43mevals[49m[43m)[49m, ]
[1;32m    521[0m [38;5;28;01mif[39;00m [38;5;28mhasattr[39m([38;5;28mself[39m, [38;5;124m'[39m[38;5;124msdos[39m[38;5;124m'[39m):
[1;32m    522[0m     [38;5;28;01mimport[39;00m [38;5;21;01mos[39;00m

File [0;32m/opt/hostedtoolcache/Python/3.8.15/x64/lib/python3.8/site-packages/BigDFT/BZ.py:94[0m, in [0;36mBandArray.__new__[0;34m(cls, *args, **kwargs)[0m
[1;32m     91[0m     shape0 [38;5;241m=[39m [38;5;241m2[39m [38;5;28;01mif[39;00m [38;5;28mlen[39m(evs[[38;5;241m1[39m]) [38;5;241m>[39m [38;5;241m0[39m [38;5;28;01melse[39;00m [38;5;241m1[39m
[1;32m     92[0m     norbs [38;5;241m=[39m [38;5;28mlist[39m([38;5;28mmap[39m([38;5;28mlen[39m, evs))
[1;32m     93[0m data [38;5;241m=[39m numpy[38;5;241m.[39mndarray[38;5;241m.[39m[38;5;21m__new__[39m([38;5;28mcls[39m, shape[38;5;241m=[39m(shape0, [38;5;28mmax[39m(norbs)),
[0;32m---> 94[0m                              dtype[38;5;241m=[39m[43mnumpy[49m[38;5;241;43m.[39;49m[43mfloat[49m)
[1;32m     95[0m data[38;5;241m.[39mfill(numpy[38;5;241m.[39mnan)
[1;32m     96[0m data[[38;5;241m0[39m, :[38;5;28mlen[39m(evs[[38;5;241m0[39m])] [38;5;241m=[39m evs[[38;5;241m0[39m]

File [0;32m/opt/hostedtoolcache/Python/3.8.15/x64/lib/python3.8/site-packages/numpy/__init__.py:284[0m, in [0;36m__getattr__[0;34m(attr)[0m
[1;32m    281[0m     [38;5;28;01mfrom[39;00m [38;5;21;01m.[39;00m[38;5;21;01mtesting[39;00m [38;5;28;01mimport[39;00m Tester
[1;32m    282[0m     [38;5;28;01mreturn[39;00m Tester
[0;32m--> 284[0m [38;5;28;01mraise[39;00m [38;5;167;01mAttributeError[39;00m([38;5;124m"[39m[38;5;124mmodule [39m[38;5;132;01m{!r}[39;00m[38;5;124m has no attribute [39m[38;5;124m"[39m
[1;32m    285[0m                      [38;5;124m"[39m[38;5;132;01m{!r}[39;00m[38;5;124m"[39m[38;5;241m.[39mformat([38;5;18m__name__[39m, attr))

[0;31mAttributeError[0m: module 'numpy' has no attribute 'float'
AttributeError: module 'numpy' has no attribute 'float'

